<?xml version="1.0" ?>
<!-- =================================================================================== -->
<!-- |    This document was autogenerated by xacro from urdf/gptpet.xacro              | -->
<!-- |    EDITING THIS FILE BY HAND IS NOT RECOMMENDED                                 | -->
<!-- =================================================================================== -->
<robot name="gptpet">
  <link name="base_link">
    <visual>
      <geometry>
        <box size="0.21 0.21 0.125"/>
      </geometry>
      <material name="Grey">
        <color rgba="0.5 0.5 0.5 1.0"/>
      </material>
    </visual>
    <collision>
      <geometry>
        <box size="0.21 0.21 0.125"/>
      </geometry>
    </collision>
    <inertial>
      <mass value="10.0"/>
      <inertia ixx="0.1" ixy="0.0" ixz="0.0" iyy="0.1" iyz="0.0" izz="0.1"/>
    </inertial>
  </link>
  <link name="wheel_left_1_link">
    <visual>
      <origin rpy="0 1.5708 0"/>
      <geometry>
        <cylinder length="0.047" radius="0.0485"/>
      </geometry>
      <material name="Black">
        <color rgba="0.1 0.1 0.1 1.0"/>
      </material>
    </visual>
    <collision>
      <origin rpy="0 1.5708 0"/>
      <geometry>
        <cylinder length="0.047" radius="0.0485"/>
      </geometry>
    </collision>
    <inertial>
      <mass value="1.0"/>
      <inertia ixx="0.001" ixy="0.0" ixz="0.0" iyy="0.001" iyz="0.0" izz="0.001"/>
    </inertial>
  </link>
  <link name="wheel_left_2_link">
    <visual>
      <origin rpy="0 1.5708 0"/>
      <geometry>
        <cylinder length="0.047" radius="0.0485"/>
      </geometry>
      <material name="Black">
        <color rgba="0.1 0.1 0.1 1.0"/>
      </material>
    </visual>
    <collision>
      <origin rpy="0 1.5708 0"/>
      <geometry>
        <cylinder length="0.047" radius="0.0485"/>
      </geometry>
    </collision>
    <inertial>
      <mass value="1.0"/>
      <inertia ixx="0.001" ixy="0.0" ixz="0.0" iyy="0.001" iyz="0.0" izz="0.001"/>
    </inertial>
  </link>
  <link name="wheel_right_1_link">
    <visual>
      <origin rpy="0 1.5708 0"/>
      <geometry>
        <cylinder length="0.047" radius="0.0485"/>
      </geometry>
      <material name="Black">
        <color rgba="0.1 0.1 0.1 1.0"/>
      </material>
    </visual>
    <collision>
      <origin rpy="0 1.5708 0"/>
      <geometry>
        <cylinder length="0.047" radius="0.0485"/>
      </geometry>
    </collision>
    <inertial>
      <mass value="1.0"/>
      <inertia ixx="0.001" ixy="0.0" ixz="0.0" iyy="0.001" iyz="0.0" izz="0.001"/>
    </inertial>
  </link>
  <link name="wheel_right_2_link">
    <visual>
      <origin rpy="0 1.5708 0"/>
      <geometry>
        <cylinder length="0.047" radius="0.0485"/>
      </geometry>
      <material name="Black">
        <color rgba="0.1 0.1 0.1 1.0"/>
      </material>
    </visual>
    <collision>
      <origin rpy="0 1.5708 0"/>
      <geometry>
        <cylinder length="0.047" radius="0.0485"/>
      </geometry>
    </collision>
    <inertial>
      <mass value="1.0"/>
      <inertia ixx="0.001" ixy="0.0" ixz="0.0" iyy="0.001" iyz="0.0" izz="0.001"/>
    </inertial>
  </link>
  <link name="base_laser_link">
    <visual>
      <!-- approximate Xbox Kinect 360 housing as a rectangular box -->
      <!-- <origin xyz="-0.35 -.08 -0.0245" rpy="0 0 0"/> -->
      <origin rpy="0 0 0"/>
      <geometry>
        <box size="0.285 0.062 0.04"/>
      </geometry>
      <material name="SensorGrey">
        <color rgba="0.2 0.2 0.2 1.0"/>
      </material>
    </visual>
    <visual>
      <origin rpy="0 0 0" xyz="0 0 -0.04"/>
      <geometry>
        <cylinder length="0.1" radius="0.017"/>
      </geometry>
      <material name="SensorGrey">
        <color rgba="0.2 0.2 0.2 1.0"/>
      </material>
    </visual>
    <collision>
      <origin rpy="0 0 0" xyz="0 0 0"/>
      <geometry>
        <box size="0.12 0.05 0.07"/>
      </geometry>
    </collision>
    <inertial>
      <mass value="0.5"/>
      <inertia ixx="0.002" ixy="0" ixz="0" iyy="0.002" iyz="0" izz="0.002"/>
    </inertial>
  </link>
  <joint name="laser_joint" type="fixed">
    <parent link="base_link"/>
    <child link="base_laser_link"/>
    <origin rpy="0 0 0" xyz="0 0.08 0.1355"/>
  </joint>
  <joint name="velocity_left_1_joint" type="continuous">
    <child link="wheel_left_1_link"/>
    <parent link="base_link"/>
    <origin rpy="0 0 0" xyz="0.1315 0.06 -0.08549999999999999"/>
    <axis xyz="0 0 1"/>
  </joint>
  <joint name="velocity_left_2_joint" type="continuous">
    <child link="wheel_left_2_link"/>
    <parent link="base_link"/>
    <origin rpy="0 0 0" xyz="-0.1315 0.06 -0.08549999999999999"/>
    <axis xyz="0 0 1"/>
  </joint>
  <joint name="velocity_right_1_joint" type="continuous">
    <child link="wheel_right_1_link"/>
    <parent link="base_link"/>
    <origin rpy="0 0 0" xyz="0.1315 -0.06 -0.08549999999999999"/>
    <axis xyz="0 0 1"/>
  </joint>
  <joint name="velocity_right_2_joint" type="continuous">
    <child link="wheel_right_2_link"/>
    <parent link="base_link"/>
    <origin rpy="0 0 0" xyz="-0.1315 -0.06 -0.08549999999999999"/>
    <axis xyz="0 0 1"/>
  </joint>
  <!-- ========= TRANSMISSIONS ========= -->
  <transmission name="trans_vel_left_1">
    <type>transmission_interface/SimpleTransmission</type>
    <joint name="velocity_left_1_joint">
      <hardwareInterface>velocity</hardwareInterface>
    </joint>
    <actuator name="motor_left_1">
      <hardwareInterface>velocity</hardwareInterface>
      <mechanicalReduction>1</mechanicalReduction>
    </actuator>
  </transmission>
  <transmission name="trans_vel_left_2">
    <type>transmission_interface/SimpleTransmission</type>
    <joint name="velocity_left_2_joint">
      <hardwareInterface>velocity</hardwareInterface>
    </joint>
    <actuator name="motor_left_2">
      <hardwareInterface>velocity</hardwareInterface>
      <mechanicalReduction>1</mechanicalReduction>
    </actuator>
  </transmission>
  <transmission name="trans_vel_right_1">
    <type>transmission_interface/SimpleTransmission</type>
    <joint name="velocity_right_1_joint">
      <hardwareInterface>velocity</hardwareInterface>
    </joint>
    <actuator name="motor_right_1">
      <hardwareInterface>velocity</hardwareInterface>
      <mechanicalReduction>1</mechanicalReduction>
    </actuator>
  </transmission>
  <transmission name="trans_vel_right_2">
    <type>transmission_interface/SimpleTransmission</type>
    <joint name="velocity_right_2_joint">
      <hardwareInterface>velocity</hardwareInterface>
    </joint>
    <actuator name="motor_right_2">
      <hardwareInterface>velocity</hardwareInterface>
      <mechanicalReduction>1</mechanicalReduction>
    </actuator>
  </transmission>
  <!-- ========= Cameras ========= -->
  <link name="camera_link"/>
  <joint name="camera_link_joint" type="fixed">
    <parent link="base_laser_link"/>
    <child link="camera_link"/>
    <origin rpy="0 0 0" xyz="0 0 0"/>
  </joint>
  <link name="camera_depth_frame"/>
  <joint name="camera_depth_joint" type="fixed">
    <parent link="camera_link"/>
    <child link="camera_depth_frame"/>
    <origin rpy="0 0 0" xyz="0 0 0"/>
  </joint>
  <link name="camera_rgb_frame"/>
  <joint name="camera_rgb_joint" type="fixed">
    <parent link="camera_link"/>
    <child link="camera_rgb_frame"/>
    <origin rpy="0 0 0" xyz="0 0 0"/>
  </joint>
  <link name="camera_rgb_optical_frame"/>
  <joint name="camera_rgb_optical_joint" type="fixed">
    <parent link="camera_rgb_frame"/>
    <child link="camera_rgb_optical_frame"/>
    <origin rpy="-1.5708 0 -1.5708" xyz="0 0 0"/>
  </joint>
  <!-- ========= ROS2_CONTROL PLUGIN ========= -->
  <ros2_control name="MecanumSystem" type="system">
    <hardware>
      <!-- Reference the exported plugin name -->
      <plugin>gptpet_hardware/GptpetHardwareInterface</plugin>
    </hardware>
    <joint name="velocity_left_1_joint">
      <command_interface name="velocity"/>
      <state_interface name="velocity"/>
    </joint>
    <joint name="velocity_left_2_joint">
      <command_interface name="velocity"/>
      <state_interface name="velocity"/>
    </joint>
    <joint name="velocity_right_1_joint">
      <command_interface name="velocity"/>
      <state_interface name="velocity"/>
    </joint>
    <joint name="velocity_right_2_joint">
      <command_interface name="velocity"/>
      <state_interface name="velocity"/>
    </joint>
  </ros2_control>
</robot>
